<?xml version="1.0"?>
<robot name="arm">

  <!-- Definisi Material -->
  <material name="silver">
    <color rgba="0.75 0.75 0.75 1"/>
  </material>

  <!-- Link World -->
  <link name="world"/>

  <!-- Link Base -->
  <link name="base_link">
    <inertial>
      <mass value="1.0"/>
      <origin rpy="0 0 0" xyz="0 0 0.025"/>
      <inertia ixx="0.0027" iyy="0.0027" izz="0.005" ixy="0" ixz="0" iyz="0"/>
    </inertial>
    <visual>
      <geometry>
        <cylinder length="0.05" radius="0.1"/>
      </geometry>
      <material name="silver"/>
      <origin rpy="0 0 0" xyz="0 0 0.025"/>
    </visual>
    <collision>
      <geometry>
        <cylinder length="0.05" radius="0.1"/>
      </geometry>
      <origin rpy="0 0 0" xyz="0 0 0.025"/>
    </collision>
  </link>

  <!-- Joint between World and Base -->
  <joint name="fixed" type="fixed">
    <parent link="world"/>
    <child link="base_link"/>
  </joint>

  <!-- Link Torso -->
  <link name="torso">
    <inertial>
      <mass value="1.0"/>
      <origin rpy="0 0 0" xyz="0 0 0"/>
      <inertia ixx="0.02146" iyy="0.02146" izz="0.00125" ixy="0" ixz="0" iyz="0"/>
    </inertial>
    <visual>
      <geometry>
        <cylinder length="0.12" radius="0.03"/>
      </geometry>
      <material name="silver"/>
      <origin rpy="0 0 0" xyz="0 0 0"/>
    </visual>
    <collision>
      <geometry>
        <cylinder length="0.12" radius="0.03"/>
      </geometry>
      <origin rpy="0 0 0" xyz="0 0 0"/>
    </collision>
  </link>

  <!-- Joint between Base and Torso -->
  <joint name="hip" type="revolute">
    <parent link="base_link"/>
    <child link="torso"/>
    <origin rpy="0 0 0" xyz="0 0 0.11"/>
    <axis xyz="0 0 1"/>
    <limit effort="30.0" velocity="1.0" upper="1.5708" lower="-1.5708"/>
  </joint>

  <!-- Link Upper Arm -->
  <link name="upper_arm">
    <inertial>
      <mass value="1.0"/>
      <origin rpy="0 0 0" xyz="0 0 0.05"/>
      <inertia ixx="0.01396" iyy="0.01396" izz="0.00125" ixy="0" ixz="0" iyz="0"/>
    </inertial>
    <visual>
      <geometry>
        <cylinder length="0.3" radius="0.03"/>
      </geometry>
      <material name="silver"/>
      <origin rpy="0 0 0" xyz="0 0 0.05"/>
    </visual>
    <collision>
      <geometry>
        <cylinder length="0.3" radius="0.03"/>
      </geometry>
      <origin rpy="0 0 0" xyz="0 0 0.05"/>
    </collision>
  </link>

  <!-- Joint between Torso and Upper Arm -->
  <joint name="shoulder" type="revolute">
    <parent link="torso"/>
    <child link="upper_arm"/>
    <origin rpy="0 1.5708 0" xyz="0.02 0.06 0.06"/>
    <axis xyz="0 1 0"/>
    <limit effort="30.0" velocity="1.0" upper="0.6981" lower="-1.5708"/>
  </joint>

  <!-- Link Forearm -->
  <link name="forearm">
    <inertial>
      <mass value="1.0"/>
      <origin rpy="0 0 0" xyz="0 0 0.12"/>
      <inertia ixx="0.01396" iyy="0.01396" izz="0.00125" ixy="0" ixz="0" iyz="0"/>
    </inertial>
    <visual>
      <geometry>
        <cylinder length="0.3" radius="0.03"/>
      </geometry>
      <material name="silver"/>
      <origin rpy="0 0 0" xyz="0 0 0.12"/>
    </visual>
    <collision>
      <geometry>
        <cylinder length="0.3" radius="0.03"/>
      </geometry>
      <origin rpy="0 0 0" xyz="0 0 0.12"/>
    </collision>
  </link>

  <!-- Joint between Upper Arm and Forearm -->
  <joint name="elbow" type="revolute">
    <parent link="upper_arm"/>
    <child link="forearm"/>
    <origin rpy="0 0 0" xyz="0 -0.055 0.1"/>
    <axis xyz="0 1 0"/>
    <limit effort="30.0" velocity="1.0" upper="1.5708" lower="-1.5708"/>
  </joint>

</robot>
